Workbook

Sheet ① 대시보드
A1: 견적서 통합 관리 대시보드
A3: 작성일: | B3: 2026-04-22
A5: ■ 주요 지표 (KPI) | D5: ■ 사업별 요약
A6: 구분 | B6: 값 | D6: 사업 구분 | E6: 건수 | F6: 총 공급가액 | G6: 총 합계금액 | H6: 수금액 | I6: 수금률
A7: 총 견적 건수 | B7: =COUNTA('② 견적리스트'!D5:D54) -> 13 | D7: 스마트 생태공장 | E7: =COUNTIF('② 견적리스트'!A5:A54,"스마트 생태공장") -> 6 | F7: =SUMIF('② 견적리스트'!A5:A54,"스마트 생태공장",'② 견적리스트'!I5:I54) -> 820000000 | G7: =SUMIF('② 견적리스트'!A5:A54,"스마트 생태공장",'② 견적리스트'!K5:K54) -> 902000000 | H7: =SUMIFS('② 견적리스트'!P5:P54,'② 견적리스트'!A5:A54,"스마트 생태공장",'② 견적리스트'!R5:R54,"수금")+SUMIFS('② 견적리스트'!T5:T54,'② 견적리스트'!A5:A54,"스마트 생태공장",'② 견적리스트'!V5:V54,"수금") -> 0 | I7: =IFERROR(H7/G7,0) -> 0
A8: 총 공급가액 | B8: =SUM('② 견적리스트'!I5:I54) -> 960000000 | D8: 섬유 제조 자동화 | E8: =COUNTIF('② 견적리스트'!A5:A54,"섬유 제조 자동화") -> 2 | F8: =SUMIF('② 견적리스트'!A5:A54,"섬유 제조 자동화",'② 견적리스트'!I5:I54) -> 140000000 | G8: =SUMIF('② 견적리스트'!A5:A54,"섬유 제조 자동화",'② 견적리스트'!K5:K54) -> 154000000 | H8: =SUMIFS('② 견적리스트'!P5:P54,'② 견적리스트'!A5:A54,"섬유 제조 자동화",'② 견적리스트'!R5:R54,"수금")+SUMIFS('② 견적리스트'!T5:T54,'② 견적리스트'!A5:A54,"섬유 제조 자동화",'② 견적리스트'!V5:V54,"수금") -> 0 | I8: =IFERROR(H8/G8,0) -> 0
A9: 총 합계금액(VAT포함) | B9: =SUM('② 견적리스트'!K5:K54) -> 1056000000 | D9: 합계 | E9: =SUM(E7:E8) -> 8 | F9: =SUM(F7:F8) -> 960000000 | G9: =SUM(G7:G8) -> 1056000000 | H9: =SUM(H7:H8) -> 0 | I9: =IFERROR(H9/F9,0) -> 0
A10: 평균 공급가액 | B10: =IFERROR(AVERAGE('② 견적리스트'!I5:I54),0) -> 120000000
A11: 수주 확정 건수 | B11: =COUNTIF('② 견적리스트'!L5:L54,"수주")+COUNTIF('② 견적리스트'!L5:L54,"설치중")+COUNTIF('② 견적리스트'!L5:L54,"완료") -> 0
A12: 진행 중 건수 | B12: =COUNTIF('② 견적리스트'!L5:L54,"진행중") -> 0
A13: 대기 중 건수 | B13: =COUNTIF('② 견적리스트'!L5:L54,"대기") -> 8
A14: 선금 수금액 | B14: =SUMIFS('② 견적리스트'!P5:P54,'② 견적리스트'!R5:R54,"수금") -> 0
A15: 잔금 수금액 | B15: =SUMIFS('② 견적리스트'!T5:T54,'② 견적리스트'!V5:V54,"수금") -> 0
A16: 총 수금액 | B16: =B14+B15 -> 0
A17: 수금 진행률(전체) | B17: =IFERROR(B16/B9,0) -> 0
A19: ■ 수요업체별 요약 | E19: ■ 공급사별 요약
A20: 수요업체 | B20: 건수 | C20: 총 공급가액 | E20: 공급사 | F20: 건수 | G20: 총 공급가액
A21: (주)을화 비산공장 | B21: =COUNTIF('② 견적리스트'!D5:D54,"(주)을화 비산공장") -> 2 | C21: =SUMIF('② 견적리스트'!D5:D54,"(주)을화 비산공장",'② 견적리스트'!I5:I54) -> 607000000 | E21: GS시스템 | F21: =COUNTIF('② 견적리스트'!E5:E54,"GS시스템") -> 7 | G21: =SUMIF('② 견적리스트'!E5:E54,"GS시스템",'② 견적리스트'!I5:I54) -> 872000000
A22: 대영염공(주) | B22: =COUNTIF('② 견적리스트'!D5:D54,"대영염공(주)") -> 2 | C22: =SUMIF('② 견적리스트'!D5:D54,"대영염공(주)",'② 견적리스트'!I5:I54) -> 70000000 | E22: 아이언텍 | F22: =COUNTIF('② 견적리스트'!E5:E54,"아이언텍") -> 1 | G22: =SUMIF('② 견적리스트'!E5:E54,"아이언텍",'② 견적리스트'!I5:I54) -> 88000000
A23: 벽진BIO텍 | B23: =COUNTIF('② 견적리스트'!D5:D54,"벽진BIO텍") -> 1 | C23: =SUMIF('② 견적리스트'!D5:D54,"벽진BIO텍",'② 견적리스트'!I5:I54) -> 70000000 | E23: 합계 | F23: =SUM(F21:F22) -> 8 | G23: =SUM(G21:G22) -> 960000000
A24: 신한염직 | B24: =COUNTIF('② 견적리스트'!D5:D54,"신한염직") -> 1 | C24: =SUMIF('② 견적리스트'!D5:D54,"신한염직",'② 견적리스트'!I5:I54) -> 62000000
A25: 우성염직 | B25: =COUNTIF('② 견적리스트'!D5:D54,"우성염직") -> 1 | C25: =SUMIF('② 견적리스트'!D5:D54,"우성염직",'② 견적리스트'!I5:I54) -> 52000000
A26: 원풍물산 | B26: =COUNTIF('② 견적리스트'!D5:D54,"원풍물산") -> 2 | C26: =SUMIF('② 견적리스트'!D5:D54,"원풍물산",'② 견적리스트'!I5:I54) -> 53000000
A27: 한국에이스 | B27: =COUNTIF('② 견적리스트'!D5:D54,"한국에이스") -> 1 | C27: =SUMIF('② 견적리스트'!D5:D54,"한국에이스",'② 견적리스트'!I5:I54) -> 46000000
A28: 합계 | B28: =SUM(B21:B27) -> 10 | C28: =SUM(C21:C27) -> 960000000
A31: ■ 프로젝트 유형별 요약
A32: 프로젝트 유형 | B32: 건수 | C32: 총 공급가액 | D32: 평균 | E32: 비중
A33: 공정수 재활용 | B33: =COUNTIF('② 견적리스트'!G5:G54,"공정수 재활용") -> 1 | C33: =SUMIF('② 견적리스트'!G5:G54,"공정수 재활용",'② 견적리스트'!I5:I54) -> 88000000 | D33: =IFERROR(AVERAGEIF('② 견적리스트'!G5:G54,"공정수 재활용",'② 견적리스트'!I5:I54),0) -> 88000000 | E33: =IFERROR(C33/SUM('② 견적리스트'!I5:I54),0) -> 0.091666667
A34: 공정액 농도 자동제어 | B34: =COUNTIF('② 견적리스트'!G5:G54,"공정액 농도 자동제어") -> 2 | C34: =SUMIF('② 견적리스트'!G5:G54,"공정액 농도 자동제어",'② 견적리스트'!I5:I54) -> 140000000 | D34: =IFERROR(AVERAGEIF('② 견적리스트'!G5:G54,"공정액 농도 자동제어",'② 견적리스트'!I5:I54),0) -> 70000000 | E34: =IFERROR(C34/SUM('② 견적리스트'!I5:I54),0) -> 0.14583333
A35: 염료/조제 스마트제어 | B35: =COUNTIF('② 견적리스트'!G5:G54,"염료/조제 스마트제어") -> 1 | C35: =SUMIF('② 견적리스트'!G5:G54,"염료/조제 스마트제어",'② 견적리스트'!I5:I54) -> 519000000 | D35: =IFERROR(AVERAGEIF('② 견적리스트'!G5:G54,"염료/조제 스마트제어",'② 견적리스트'!I5:I54),0) -> 519000000 | E35: =IFERROR(C35/SUM('② 견적리스트'!I5:I54),0) -> 0.540625
A36: 통합 모니터링 시스템 | B36: =COUNTIF('② 견적리스트'!G5:G54,"통합 모니터링 시스템") -> 4 | C36: =SUMIF('② 견적리스트'!G5:G54,"통합 모니터링 시스템",'② 견적리스트'!I5:I54) -> 213000000 | D36: =IFERROR(AVERAGEIF('② 견적리스트'!G5:G54,"통합 모니터링 시스템",'② 견적리스트'!I5:I54),0) -> 53250000 | E36: =IFERROR(C36/SUM('② 견적리스트'!I5:I54),0) -> 0.221875

Sheet ② 견적리스트
A1: 견적서 통합 리스트 (사업별 구분 / 선금·잔금·설치일정 관리)
A2: ※ 공급가액 = 부가세 별도 / 합계금액 = 공급가액+부가세 / 선금·잔금 비율의 합은 100% (기본값 50:50, 직접 수정 가능) / 진행상태 및 선금·잔금 상태는 드롭다운
A3: 기본 정보 | I3: 금액 | L3: 진행/설치 | O3: 선금 관리 | S3: 잔금 관리 | W3: 수금률 | X3: 담당/비고
A4: 사업 구분 | B4: No | C4: 견적번호 | D4: 수요업체 | E4: 공급사 | F4: 견적일 | G4: 프로젝트 유형 | H4: 견적명 | I4: 공급가액(원) | J4: 부가세(원) | K4: 합계금액(원) | L4: 진행상태 | M4: 설치 시작일 | N4: 설치 종료일 | O4: 선금 비율(%) | P4: 선금 금액(원) | Q4: 선금 입금일 | R4: 선금 상태 | S4: 잔금 비율(%) | T4: 잔금 금액(원) | U4: 잔금 입금일 | V4: 잔금 상태 | W4: 수금 진행률 | X4: 담당자 | Y4: 연락처 | Z4: 비고
A5: 스마트 생태공장 | B5: 1 | C5: 20260105-0001-01 | D5: (주)을화 비산공장 | E5: GS시스템 | F5: 2026-01-05 | G5: 염료/조제 스마트제어 | H5: 염료,조제 스마트제어시스템 | I5: 519000000 | J5: =I5*0.1 -> 51900000 | K5: =I5+J5 -> 570900000 | L5: 대기 | O5: 0.5 | P5: =K5*O5 -> 285450000 | R5: 미수금 | S5: =1-O5 -> 0.5 | T5: =K5*S5 -> 285450000 | V5: 미수금 | W5: =IFERROR((IF(R5="수금",P5,0)+IF(V5="수금",T5,0))/K5,0) -> 0 | X5: 오영정 | Y5: 010-2005-0476 | Z5: 가성소다·블랙염료 / DCPM 11대 / 내역서 포함
A6: 스마트 생태공장 | B6: 2 | C6: 20260114-0001 | D6: (주)을화 비산공장 | E6: 아이언텍 | F6: 2026-01-14 | G6: 공정수 재활용 | H6: 공정수 재활용 시스템 | I6: 88000000 | J6: =I6*0.1 -> 8800000 | K6: =I6+J6 -> 96800000 | L6: 대기 | O6: 0.5 | P6: =K6*O6 -> 48400000 | R6: 미수금 | S6: =1-O6 -> 0.5 | T6: =K6*S6 -> 48400000 | V6: 미수금 | W6: =IFERROR((IF(R6="수금",P6,0)+IF(V6="수금",T6,0))/K6,0) -> 0 | X6: 오정수 | Y6: 010-8857-0476 | Z6: STS 30톤 저장탱크 / 부가세 포함 총 96,800,000
A7: 스마트 생태공장 | B7: 3 | C7: 20260105-0001-02 | D7: 신한염직 | E7: GS시스템 | F7: 2026-01-05 | G7: 통합 모니터링 시스템 | H7: 통합 모니터링 시스템 | I7: 62000000 | J7: =I7*0.1 -> 6200000 | K7: =I7+J7 -> 68200000 | L7: 대기 | O7: 0.5 | P7: =K7*O7 -> 34100000 | R7: 미수금 | S7: =1-O7 -> 0.5 | T7: =K7*S7 -> 34100000 | V7: 미수금 | W7: =IFERROR((IF(R7="수금",P7,0)+IF(V7="수금",T7,0))/K7,0) -> 0 | X7: 오영정 | Y7: 010-2005-0476 | Z7: RO용수·열교환온수회수 마그네틱 유량계 포함
A8: 스마트 생태공장 | B8: 4 | C8: 20260105-0001-03 | D8: 원풍물산 | E8: GS시스템 | F8: 2026-01-05 | G8: 통합 모니터링 시스템 | H8: 통합 모니터링 시스템 | I8: 53000000 | J8: =I8*0.1 -> 5300000 | K8: =I8+J8 -> 58300000 | L8: 대기 | O8: 0.5 | P8: =K8*O8 -> 29150000 | R8: 미수금 | S8: =1-O8 -> 0.5 | T8: =K8*S8 -> 29150000 | V8: 미수금 | W8: =IFERROR((IF(R8="수금",P8,0)+IF(V8="수금",T8,0))/K8,0) -> 0 | X8: 오영정 | Y8: 010-2005-0476 | Z8: 텐터기 가스·압출기·집진기 전력량계
A9: 스마트 생태공장 | B9: 5 | C9: 20260105-0001-04 | D9: 우성염직 | E9: GS시스템 | F9: 2026-01-05 | G9: 통합 모니터링 시스템 | H9: 통합 모니터링 시스템 | I9: 52000000 | J9: =I9*0.1 -> 5200000 | K9: =I9+J9 -> 57200000 | L9: 대기 | O9: 0.5 | P9: =K9*O9 -> 28600000 | R9: 미수금 | S9: =1-O9 -> 0.5 | T9: =K9*S9 -> 28600000 | V9: 미수금 | W9: =IFERROR((IF(R9="수금",P9,0)+IF(V9="수금",T9,0))/K9,0) -> 0 | X9: 오영정 | Y9: 010-2005-0476 | Z9: 로터리날염기 스팀·용수 유량계
A10: 스마트 생태공장 | B10: 6 | C10: 20260105-0001-05 | D10: 한국에이스 | E10: GS시스템 | F10: 2026-01-05 | G10: 통합 모니터링 시스템 | H10: 통합 모니터링 시스템 | I10: 46000000 | J10: =I10*0.1 -> 4600000 | K10: =I10+J10 -> 50600000 | L10: 대기 | O10: 0.5 | P10: =K10*O10 -> 25300000 | R10: 미수금 | S10: =1-O10 -> 0.5 | T10: =K10*S10 -> 25300000 | V10: 미수금 | W10: =IFERROR((IF(R10="수금",P10,0)+IF(V10="수금",T10,0))/K10,0) -> 0 | X10: 오영정 | Y10: 010-2005-0476 | Z10: 텐터기 가스·전력 / 유량계 장착 확인
A11: 섬유 제조 자동화 | B11: 7 | C11: 20260316-0001-01 | D11: 대영염공(주) | E11: GS시스템 | F11: 2026-03-16 | G11: 공정액 농도 자동제어 | H11: 스마트 공정액 농도 자동제어 시스템 | I11: 70000000 | J11: =I11*0.1 -> 7000000 | K11: =I11+J11 -> 77000000 | L11: 대기 | O11: 0.5 | P11: =K11*O11 -> 38500000 | R11: 미수금 | S11: =1-O11 -> 0.5 | T11: =K11*S11 -> 38500000 | V11: 미수금 | W11: =IFERROR((IF(R11="수금",P11,0)+IF(V11="수금",T11,0))/K11,0) -> 0 | X11: 오영정 | Y11: 010-2005-0476 | Z11: 주설비 52M + 자동제어밸브 10M + 배관공사 5M + 현장설치 3M
A12: 섬유 제조 자동화 | B12: 8 | C12: 20260316-0001-02 | D12: 벽진BIO텍 | E12: GS시스템 | F12: 2026-03-16 | G12: 공정액 농도 자동제어 | H12: 스마트 공정액 농도 자동제어 시스템 | I12: 70000000 | J12: =I12*0.1 -> 7000000 | K12: =I12+J12 -> 77000000 | L12: 대기 | O12: 0.5 | P12: =K12*O12 -> 38500000 | R12: 미수금 | S12: =1-O12 -> 0.5 | T12: =K12*S12 -> 38500000 | V12: 미수금 | W12: =IFERROR((IF(R12="수금",P12,0)+IF(V12="수금",T12,0))/K12,0) -> 0 | X12: 오영정 | Y12: 010-2005-0476 | Z12: 주설비 52M + 자동제어밸브 10M + 배관공사 5M + 현장설치 3M
A13: 화학안전 사업장 조성 | D13: 을화 | J13: =IF(I13="","",I13*0.1) | K13: =IF(I13="","",I13+J13) | P13: =IF(AND(K13<>"",O13<>""),K13*O13,"") | S13: =IF(O13="","",1-O13) | T13: =IF(AND(K13<>"",S13<>""),K13*S13,"") | W13: =IF(K13="","",IFERROR((IF(R13="수금",P13,0)+IF(V13="수금",T13,0))/K13,0))
A14: 공정저탄소 | D14: 원풍물산 | J14: =IF(I14="","",I14*0.1) | K14: =IF(I14="","",I14+J14) | P14: =IF(AND(K14<>"",O14<>""),K14*O14,"") | S14: =IF(O14="","",1-O14) | T14: =IF(AND(K14<>"",S14<>""),K14*S14,"") | W14: =IF(K14="","",IFERROR((IF(R14="수금",P14,0)+IF(V14="수금",T14,0))/K14,0))
A15: 공정저탄소 | D15: 통합 | J15: =IF(I15="","",I15*0.1) | K15: =IF(I15="","",I15+J15) | P15: =IF(AND(K15<>"",O15<>""),K15*O15,"") | S15: =IF(O15="","",1-O15) | T15: =IF(AND(K15<>"",S15<>""),K15*S15,"") | W15: =IF(K15="","",IFERROR((IF(R15="수금",P15,0)+IF(V15="수금",T15,0))/K15,0))
A16: 상생협력 실증 프로그램 | D16: 대영염공(주) | J16: =IF(I16="","",I16*0.1) | K16: =IF(I16="","",I16+J16) | P16: =IF(AND(K16<>"",O16<>""),K16*O16,"") | S16: =IF(O16="","",1-O16) | T16: =IF(AND(K16<>"",S16<>""),K16*S16,"") | W16: =IF(K16="","",IFERROR((IF(R16="수금",P16,0)+IF(V16="수금",T16,0))/K16,0))
A17: 공정저탄소 | D17: 부성 | J17: =IF(I17="","",I17*0.1) | K17: =IF(I17="","",I17+J17) | P17: =IF(AND(K17<>"",O17<>""),K17*O17,"") | S17: =IF(O17="","",1-O17) | T17: =IF(AND(K17<>"",S17<>""),K17*S17,"") | W17: =IF(K17="","",IFERROR((IF(R17="수금",P17,0)+IF(V17="수금",T17,0))/K17,0))
J18: =IF(I18="","",I18*0.1) | K18: =IF(I18="","",I18+J18) | P18: =IF(AND(K18<>"",O18<>""),K18*O18,"") | S18: =IF(O18="","",1-O18) | T18: =IF(AND(K18<>"",S18<>""),K18*S18,"") | W18: =IF(K18="","",IFERROR((IF(R18="수금",P18,0)+IF(V18="수금",T18,0))/K18,0))
J19: =IF(I19="","",I19*0.1) | K19: =IF(I19="","",I19+J19) | P19: =IF(AND(K19<>"",O19<>""),K19*O19,"") | S19: =IF(O19="","",1-O19) | T19: =IF(AND(K19<>"",S19<>""),K19*S19,"") | W19: =IF(K19="","",IFERROR((IF(R19="수금",P19,0)+IF(V19="수금",T19,0))/K19,0))
J20: =IF(I20="","",I20*0.1) | K20: =IF(I20="","",I20+J20) | P20: =IF(AND(K20<>"",O20<>""),K20*O20,"") | S20: =IF(O20="","",1-O20) | T20: =IF(AND(K20<>"",S20<>""),K20*S20,"") | W20: =IF(K20="","",IFERROR((IF(R20="수금",P20,0)+IF(V20="수금",T20,0))/K20,0))
J21: =IF(I21="","",I21*0.1) | K21: =IF(I21="","",I21+J21) | P21: =IF(AND(K21<>"",O21<>""),K21*O21,"") | S21: =IF(O21="","",1-O21) | T21: =IF(AND(K21<>"",S21<>""),K21*S21,"") | W21: =IF(K21="","",IFERROR((IF(R21="수금",P21,0)+IF(V21="수금",T21,0))/K21,0))
J22: =IF(I22="","",I22*0.1) | K22: =IF(I22="","",I22+J22) | P22: =IF(AND(K22<>"",O22<>""),K22*O22,"") | S22: =IF(O22="","",1-O22) | T22: =IF(AND(K22<>"",S22<>""),K22*S22,"") | W22: =IF(K22="","",IFERROR((IF(R22="수금",P22,0)+IF(V22="수금",T22,0))/K22,0))
J23: =IF(I23="","",I23*0.1) | K23: =IF(I23="","",I23+J23) | P23: =IF(AND(K23<>"",O23<>""),K23*O23,"") | S23: =IF(O23="","",1-O23) | T23: =IF(AND(K23<>"",S23<>""),K23*S23,"") | W23: =IF(K23="","",IFERROR((IF(R23="수금",P23,0)+IF(V23="수금",T23,0))/K23,0))
J24: =IF(I24="","",I24*0.1) | K24: =IF(I24="","",I24+J24) | P24: =IF(AND(K24<>"",O24<>""),K24*O24,"") | S24: =IF(O24="","",1-O24) | T24: =IF(AND(K24<>"",S24<>""),K24*S24,"") | W24: =IF(K24="","",IFERROR((IF(R24="수금",P24,0)+IF(V24="수금",T24,0))/K24,0))
J25: =IF(I25="","",I25*0.1) | K25: =IF(I25="","",I25+J25) | P25: =IF(AND(K25<>"",O25<>""),K25*O25,"") | S25: =IF(O25="","",1-O25) | T25: =IF(AND(K25<>"",S25<>""),K25*S25,"") | W25: =IF(K25="","",IFERROR((IF(R25="수금",P25,0)+IF(V25="수금",T25,0))/K25,0))
J26: =IF(I26="","",I26*0.1) | K26: =IF(I26="","",I26+J26) | P26: =IF(AND(K26<>"",O26<>""),K26*O26,"") | S26: =IF(O26="","",1-O26) | T26: =IF(AND(K26<>"",S26<>""),K26*S26,"") | W26: =IF(K26="","",IFERROR((IF(R26="수금",P26,0)+IF(V26="수금",T26,0))/K26,0))
J27: =IF(I27="","",I27*0.1) | K27: =IF(I27="","",I27+J27) | P27: =IF(AND(K27<>"",O27<>""),K27*O27,"") | S27: =IF(O27="","",1-O27) | T27: =IF(AND(K27<>"",S27<>""),K27*S27,"") | W27: =IF(K27="","",IFERROR((IF(R27="수금",P27,0)+IF(V27="수금",T27,0))/K27,0))
J28: =IF(I28="","",I28*0.1) | K28: =IF(I28="","",I28+J28) | P28: =IF(AND(K28<>"",O28<>""),K28*O28,"") | S28: =IF(O28="","",1-O28) | T28: =IF(AND(K28<>"",S28<>""),K28*S28,"") | W28: =IF(K28="","",IFERROR((IF(R28="수금",P28,0)+IF(V28="수금",T28,0))/K28,0))
J29: =IF(I29="","",I29*0.1) | K29: =IF(I29="","",I29+J29) | P29: =IF(AND(K29<>"",O29<>""),K29*O29,"") | S29: =IF(O29="","",1-O29) | T29: =IF(AND(K29<>"",S29<>""),K29*S29,"") | W29: =IF(K29="","",IFERROR((IF(R29="수금",P29,0)+IF(V29="수금",T29,0))/K29,0))
... J54: =IF(I54="","",I54*0.1) | K54: =IF(I54="","",I54+J54) | P54: =IF(AND(K54<>"",O54<>""),K54*O54,"") | S54: =IF(O54="","",1-O54) | T54: =IF(AND(K54<>"",S54<>""),K54*S54,"") | W54: =IF(K54="","",IFERROR((IF(R54="수금",P54,0)+IF(V54="수금",T54,0))/K54,0))
A55: 합계 | I55: =SUM(I5:I54) -> 960000000 | J55: =SUM(J5:J54) -> 96000000 | K55: =SUM(K5:K54) -> 1056000000 | P55: =SUMIFS(P5:P54,R5:R54,"수금") -> 0 | R55: 수금완료 | T55: =SUMIFS(T5:T54,V5:V54,"수금") -> 0 | V55: 수금완료 | W55: =IFERROR((P55+T55)/K55,0) -> 0

Sheet ③ 수주·수금 현황
A1: 수주 및 수금 현황 관리
A3: 사업 구분 | B3: 수요업체 | C3: 공급사 | D3: 합계금액 | E3: 진행상태 | F3: 설치 시작 | G3: 설치 종료 | H3: 선금 금액 | I3: 선금 상태 | J3: 잔금 금액 | K3: 잔금 상태 | L3: 수금률
A4: ='② 견적리스트'!A5 -> 스마트 생태공장 | B4: ='② 견적리스트'!D5 -> (주)을화 비산공장 | C4: ='② 견적리스트'!E5 -> GS시스템 | D4: ='② 견적리스트'!K5 -> 570900000 | E4: ='② 견적리스트'!L5 -> 대기 | F4: ='② 견적리스트'!M5 -> 0 | G4: ='② 견적리스트'!N5 -> 0 | H4: ='② 견적리스트'!P5 -> 285450000 | I4: ='② 견적리스트'!R5 -> 미수금 | J4: ='② 견적리스트'!T5 -> 285450000 | K4: ='② 견적리스트'!V5 -> 미수금 | L4: ='② 견적리스트'!W5 -> 0
A5: ='② 견적리스트'!A6 -> 스마트 생태공장 | B5: ='② 견적리스트'!D6 -> (주)을화 비산공장 | C5: ='② 견적리스트'!E6 -> 아이언텍 | D5: ='② 견적리스트'!K6 -> 96800000 | E5: ='② 견적리스트'!L6 -> 대기 | F5: ='② 견적리스트'!M6 -> 0 | G5: ='② 견적리스트'!N6 -> 0 | H5: ='② 견적리스트'!P6 -> 48400000 | I5: ='② 견적리스트'!R6 -> 미수금 | J5: ='② 견적리스트'!T6 -> 48400000 | K5: ='② 견적리스트'!V6 -> 미수금 | L5: ='② 견적리스트'!W6 -> 0
A6: ='② 견적리스트'!A7 -> 스마트 생태공장 | B6: ='② 견적리스트'!D7 -> 신한염직 | C6: ='② 견적리스트'!E7 -> GS시스템 | D6: ='② 견적리스트'!K7 -> 68200000 | E6: ='② 견적리스트'!L7 -> 대기 | F6: ='② 견적리스트'!M7 -> 0 | G6: ='② 견적리스트'!N7 -> 0 | H6: ='② 견적리스트'!P7 -> 34100000 | I6: ='② 견적리스트'!R7 -> 미수금 | J6: ='② 견적리스트'!T7 -> 34100000 | K6: ='② 견적리스트'!V7 -> 미수금 | L6: ='② 견적리스트'!W7 -> 0
A7: ='② 견적리스트'!A8 -> 스마트 생태공장 | B7: ='② 견적리스트'!D8 -> 원풍물산 | C7: ='② 견적리스트'!E8 -> GS시스템 | D7: ='② 견적리스트'!K8 -> 58300000 | E7: ='② 견적리스트'!L8 -> 대기 | F7: ='② 견적리스트'!M8 -> 0 | G7: ='② 견적리스트'!N8 -> 0 | H7: ='② 견적리스트'!P8 -> 29150000 | I7: ='② 견적리스트'!R8 -> 미수금 | J7: ='② 견적리스트'!T8 -> 29150000 | K7: ='② 견적리스트'!V8 -> 미수금 | L7: ='② 견적리스트'!W8 -> 0
A8: ='② 견적리스트'!A9 -> 스마트 생태공장 | B8: ='② 견적리스트'!D9 -> 우성염직 | C8: ='② 견적리스트'!E9 -> GS시스템 | D8: ='② 견적리스트'!K9 -> 57200000 | E8: ='② 견적리스트'!L9 -> 대기 | F8: ='② 견적리스트'!M9 -> 0 | G8: ='② 견적리스트'!N9 -> 0 | H8: ='② 견적리스트'!P9 -> 28600000 | I8: ='② 견적리스트'!R9 -> 미수금 | J8: ='② 견적리스트'!T9 -> 28600000 | K8: ='② 견적리스트'!V9 -> 미수금 | L8: ='② 견적리스트'!W9 -> 0
A9: ='② 견적리스트'!A10 -> 스마트 생태공장 | B9: ='② 견적리스트'!D10 -> 한국에이스 | C9: ='② 견적리스트'!E10 -> GS시스템 | D9: ='② 견적리스트'!K10 -> 50600000 | E9: ='② 견적리스트'!L10 -> 대기 | F9: ='② 견적리스트'!M10 -> 0 | G9: ='② 견적리스트'!N10 -> 0 | H9: ='② 견적리스트'!P10 -> 25300000 | I9: ='② 견적리스트'!R10 -> 미수금 | J9: ='② 견적리스트'!T10 -> 25300000 | K9: ='② 견적리스트'!V10 -> 미수금 | L9: ='② 견적리스트'!W10 -> 0
A10: ='② 견적리스트'!A11 -> 섬유 제조 자동화 | B10: ='② 견적리스트'!D11 -> 대영염공(주) | C10: ='② 견적리스트'!E11 -> GS시스템 | D10: ='② 견적리스트'!K11 -> 77000000 | E10: ='② 견적리스트'!L11 -> 대기 | F10: ='② 견적리스트'!M11 -> 0 | G10: ='② 견적리스트'!N11 -> 0 | H10: ='② 견적리스트'!P11 -> 38500000 | I10: ='② 견적리스트'!R11 -> 미수금 | J10: ='② 견적리스트'!T11 -> 38500000 | K10: ='② 견적리스트'!V11 -> 미수금 | L10: ='② 견적리스트'!W11 -> 0
A11: ='② 견적리스트'!A12 -> 섬유 제조 자동화 | B11: ='② 견적리스트'!D12 -> 벽진BIO텍 | C11: ='② 견적리스트'!E12 -> GS시스템 | D11: ='② 견적리스트'!K12 -> 77000000 | E11: ='② 견적리스트'!L12 -> 대기 | F11: ='② 견적리스트'!M12 -> 0 | G11: ='② 견적리스트'!N12 -> 0 | H11: ='② 견적리스트'!P12 -> 38500000 | I11: ='② 견적리스트'!R12 -> 미수금 | J11: ='② 견적리스트'!T12 -> 38500000 | K11: ='② 견적리스트'!V12 -> 미수금 | L11: ='② 견적리스트'!W12 -> 0
A12: ='② 견적리스트'!A13 -> 화학안전 사업장 조성 | B12: ='② 견적리스트'!D13 -> 을화 | C12: ='② 견적리스트'!E13 -> 0 | D12: ='② 견적리스트'!K13 | E12: ='② 견적리스트'!L13 -> 0 | F12: ='② 견적리스트'!M13 -> 0 | G12: ='② 견적리스트'!N13 -> 0 | H12: ='② 견적리스트'!P13 | I12: ='② 견적리스트'!R13 -> 0 | J12: ='② 견적리스트'!T13 | K12: ='② 견적리스트'!V13 -> 0 | L12: ='② 견적리스트'!W13
A13: ='② 견적리스트'!A14 -> 공정저탄소 | B13: ='② 견적리스트'!D14 -> 원풍물산 | C13: ='② 견적리스트'!E14 -> 0 | D13: ='② 견적리스트'!K14 | E13: ='② 견적리스트'!L14 -> 0 | F13: ='② 견적리스트'!M14 -> 0 | G13: ='② 견적리스트'!N14 -> 0 | H13: ='② 견적리스트'!P14 | I13: ='② 견적리스트'!R14 -> 0 | J13: ='② 견적리스트'!T14 | K13: ='② 견적리스트'!V14 -> 0 | L13: ='② 견적리스트'!W14
A14: ='② 견적리스트'!A15 -> 공정저탄소 | B14: ='② 견적리스트'!D15 -> 통합 | C14: ='② 견적리스트'!E15 -> 0 | D14: ='② 견적리스트'!K15 | E14: ='② 견적리스트'!L15 -> 0 | F14: ='② 견적리스트'!M15 -> 0 | G14: ='② 견적리스트'!N15 -> 0 | H14: ='② 견적리스트'!P15 | I14: ='② 견적리스트'!R15 -> 0 | J14: ='② 견적리스트'!T15 | K14: ='② 견적리스트'!V15 -> 0 | L14: ='② 견적리스트'!W15
A15: ='② 견적리스트'!A16 -> 상생협력 실증 프로그램 | B15: ='② 견적리스트'!D16 -> 대영염공(주) | C15: ='② 견적리스트'!E16 -> 0 | D15: ='② 견적리스트'!K16 | E15: ='② 견적리스트'!L16 -> 0 | F15: ='② 견적리스트'!M16 -> 0 | G15: ='② 견적리스트'!N16 -> 0 | H15: ='② 견적리스트'!P16 | I15: ='② 견적리스트'!R16 -> 0 | J15: ='② 견적리스트'!T16 | K15: ='② 견적리스트'!V16 -> 0 | L15: ='② 견적리스트'!W16
... A53: ='② 견적리스트'!A54 -> 0 | B53: ='② 견적리스트'!D54 -> 0 | C53: ='② 견적리스트'!E54 -> 0 | D53: ='② 견적리스트'!K54 | E53: ='② 견적리스트'!L54 -> 0 | F53: ='② 견적리스트'!M54 -> 0 | G53: ='② 견적리스트'!N54 -> 0 | H53: ='② 견적리스트'!P54 | I53: ='② 견적리스트'!R54 -> 0 | J53: ='② 견적리스트'!T54 | K53: ='② 견적리스트'!V54 -> 0 | L53: ='② 견적리스트'!W54

Sheet ④ 업체별 상세
A1: 수요업체별 견적 상세 및 주요 품목
A3: 사업 구분 | B3: 수요업체 | C3: 프로젝트 유형 | D3: 공급사 | E3: 공급가액 | F3: 주요 계측/설비 품목 | G3: 대상 공정/설비 | H3: 비고
A4: 섬유 제조 자동화 | B4: 대영염공(주) | C4: 공정액 농도 자동제어 | D4: GS시스템 | E4: 70000000 | F4: 스마트 공정액 농도 자동제어 시스템(주설비), 자동제어밸브(약품 공급 제어), 배관공사, 현장설치 및 시운전 | G4: 약품 공급 라인, 공정액 농도 제어 | H4: VAT 포함 77,000,000 / 주설비 52M + 밸브 10M + 배관 5M + 설치 3M
A5: 섬유 제조 자동화 | B5: 벽진BIO텍 | C5: 공정액 농도 자동제어 | D5: GS시스템 | E5: 70000000 | F5: 스마트 공정액 농도 자동제어 시스템(주설비), 자동제어밸브(약품 공급 제어), 배관공사, 현장설치 및 시운전 | G5: 약품 공급 라인, 공정액 농도 제어 | H5: VAT 포함 77,000,000 / 대영염공과 동일 사양
A6: 스마트 생태공장 | B6: (주)을화 비산공장 | C6: 염료/조제 스마트제어 | D6: GS시스템 | E6: 519000000 | F6: 자동제어판넬, DCPM 프로그램, 염색기 제어반(11대), 가성소다 유량계, 블랙염료 계량송출, 화학용 펌프, 레벨 트랜스미터 | G6: 가성소다·블랙염료 계량송출, 염색기 11대 DCPM, 로터리워셔, 텐터기, 스카챠 | H6: 최대규모 / 내역서 상세 / 세부 품목 내역 별도 시트 참조
A7: 스마트 생태공장 | B7: (주)을화 비산공장 | C7: 공정수 재활용 | D7: 아이언텍 | E7: 88000000 | F7: STS 30톤 원형 저장탱크, Shell/Bottom/Top, 롤벤딩, 탱크지지 프레임, 80A 밸브(투입/배출/드레인/벤트), 외부사다리, 상부난간 | G7: 공정수 재활용 저장탱크 제작 및 현장설치 | H7: 부가세 포함 총 96,800,000 / 제관공·용접공·조립공 인건비 포함
A8: 스마트 생태공장 | B8: 신한염직 | C8: 통합 모니터링 시스템 | D8: GS시스템 | E8: 62000000 | F8: RO용수 마그네틱 유량계, 열교환온수회수·용수 마그네틱 유량계(2EA), 터빈 가스미터, 전력량계, 모니터링 프로그램 | G8: RO, 열교환온수회수, 용수, 텐터기 | H8: 용수·스팀 MODBUS-RTU 통신형 유량계 장착 필수
A9: 스마트 생태공장 | B9: 원풍물산 | C9: 통합 모니터링 시스템 | D9: GS시스템 | E9: 53000000 | F9: 터빈 가스미터(텐터기), 전력량계(압출기·집진기), 모니터링 프로그램, 통신/전원 케이블 덕트 | G9: 텐터기, 압출기, 집진기 | H9: 용수·스팀 MODBUS-RTU 통신형 유량계 장착 필수
A10: 스마트 생태공장 | B10: 우성염직 | C10: 통합 모니터링 시스템 | D10: GS시스템 | E10: 52000000 | F10: 스팀 볼텍스 유량계, 용수 마그네틱 유량계, 전력량계(스티머·로터리날염기), 모니터링 프로그램 | G10: 로터리날염기, 스티머 | H10: 통신형 유량계 필수
A11: 스마트 생태공장 | B11: 한국에이스 | C11: 통합 모니터링 시스템 | D11: GS시스템 | E11: 46000000 | F11: 터빈 가스미터(텐터기), 전력량계, 모니터링 프로그램, 통신/전원 케이블, 에너지 데이터 송수신 장치 | G11: 텐터기 | H11: 유량계 사전 장착 확인 / 최소 규모
A12: 합계 | E12: =SUM(E4:E11) -> 960000000

Sheet ⑤ 을화 염료조제 내역
A1: (주)을화 비산공장 - 염료/조제 스마트제어시스템 세부 내역 (GS시스템)
A2: 견적금액: 519,000,000원 (부가세 제외)
A4: ■ 내역 총괄표
A5: 비목 | B5: 세부 비목 | C5: 금액(원) | D5: 비중 | E5: 비고
A6: 재료비 | B6: 직접재료비 | C6: 504750000 | D6: =C6/$C$9 -> 0.97254335 | E6: 세부내역서 참조
A7: 노무비 | B7: 직접노무비 | C7: 13750000 | D7: =C7/$C$9 -> 0.026493256 | E7: 세부내역서 참조
A8: 경비 | B8: 운반비 | C8: 500000 | D8: =C8/$C$9 -> 0.00096339114 | E8: 차량 5회 × 100,000
A9: 제조원가 합계 | C9: =SUM(C6:C8) -> 519000000 | D9: =C9/$C$9 -> 1 | E9: 재료비+노무비+경비
A11: ■ 파트별 재료비 구성
A12: 파트명 | B12: 주요 내용 | C12: 금액(원) | D12: 비중(재료비 기준) | E12: 비고
A13: 염색기 DCPM | B13: DCPM 프로그램, 염색기 제어반 11대, 485통신선, 모니터, 전용PC, 전선덕트 | C13: 295167000 | D13: =C13/$C$6 -> 0.5847786 | E13: 최대 비중
A14: 블랙염료 계량송출 파트 | B14: 자동제어판넬, 펌프, 유량계, 자동/수동 밸브, 배관 일식 | C14: 81416000 | D14: =C14/$C$6 -> 0.16129965
A15: 가성소다 송출 파트 | B15: 자동제어판넬, 가성소다 유량계, 화학용펌프, 용수펌프, Y밸브 | C15: 68767000 | D15: =C15/$C$6 -> 0.13623972
A16: 통합 모니터링 시스템 | B16: 스팀/용수 유량계, 가스미터, 전력량계, 모니터링 프로그램, 케이블 | C16: 59400000 | D16: =C16/$C$6 -> 0.11768202
A17: 재료비 합계 | C17: =SUM(C13:C16) -> 504750000 | D17: =C17/$C$6 -> 1
A19: ■ 노무비 상세
A20: 항목 | B20: 구분 | C20: M/D | D20: 단가(원) | E20: 금액(원)
A21: 염료 장치제작 인건비 | B21: 블랙염료 계량 송출파트 | C21: 20 | D21: 250000 | E21: =C21*D21 -> 5000000
A22: DCPM 배선 인건비 | B22: 염색기 DCPM 파트 | C22: 10 | D22: 250000 | E22: =C22*D22 -> 2500000
A23: 조제 장치제작 인건비 | B23: 가성소다 계량 송출파트 | C23: 10 | D23: 250000 | E23: =C23*D23 -> 2500000
A24: 모니터링 시스템 제작 | B24: 모니터링 프로그램 외 | C24: 10 | D24: 250000 | E24: =C24*D24 -> 2500000
A25: 현장설치 | B25: 현장 | C25: 5 | D25: 250000 | E25: =C25*D25 -> 1250000
A26: 노무비 합계 | E26: =SUM(E21:E25) -> 13750000

Sheet ⑥ 안내
A1: 파일 사용 안내 (v2)
A3: ■ 시트 구성
A4: ① 대시보드 | B4: KPI + 사업별·업체별·공급사별·프로젝트 유형별 집계 (모두 ②에서 자동 계산)
A5: ② 견적리스트 | B5: 메인 관리 시트. 사업구분·진행상태·설치일정·선금/잔금 관리 전부 여기서 입력
A6: ③ 수주·수금 현황 | B6: 파이프라인 뷰. 설치일정·선금·잔금·수금률 한눈에 보기 (② 참조)
A7: ④ 업체별 상세 | B7: 수요업체별 견적 상세 및 주요 품목 (비교용, 사업구분 포함)
A8: ⑤ 을화 염료조제 내역 | B8: (주)을화 비산공장 염료/조제 519M 세부 내역 (재료비·노무비 분해)
A9: ⑥ 안내 | B9: 이 시트
A11: ■ 사업 구분
A12: 스마트 생태공장 | B12: 통합 모니터링·염료조제·공정수 재활용 등 6건 | C12: 연청색 배경
A13: 섬유 제조 자동화 | B13: 공정액 농도 자동제어 2건 (대영염공, 벽진BIO텍) | C13: 연녹색 배경
A14: 향후 추가 | B14: ② 시트 A열 드롭다운에서 새 사업명 직접 입력 가능
A16: ■ 진행상태 범례 (7단계)
A17: 대기 | B17: 견적 발송 후 고객 검토 대기 | C17: 연분홍
A18: 진행중 | B18: 협상 / 사양 조정 / PO 발행 대기 | C18: 노랑
A19: 수주 | B19: 계약 체결, 발주 확정 | C19: 연녹
A20: 설치중 | B20: 현장 설치 진행 중 | C20: 노랑
A21: 완료 | B21: 설치 완료 / 시운전 종료 | C21: 연녹
A22: 실주 | B22: 타사 수주 / 무산 | C22: 연분홍
A23: 보류 | B23: 예산 미확정 / 프로젝트 연기 | C23: 연분홍
A25: ■ 선금/잔금 상태 (4단계)
A26: 미수금 | B26: 청구 전 / 계약 후 대기 | C26: 연분홍
A27: 청구 | B27: 세금계산서 발행 / 입금 대기 | C27: 노랑
A28: 수금 | B28: 입금 완료 (수금 진행률에 반영) | C28: 연녹
A29: 지연 | B29: 기일 초과 / 미납 | C29: 연분홍
A31: ■ 자동 계산 수식
A32: 부가세 | B32: 공급가액 × 10% | C32: J열
A33: 합계금액 | B33: 공급가액 + 부가세 | C33: K열
A34: 선금 금액 | B34: 합계금액 × 선금 비율 (기본 50%, 수정 가능) | C34: P열
A35: 잔금 비율 | B35: 1 - 선금 비율 (자동) | C35: S열
A36: 잔금 금액 | B36: 합계금액 × 잔금 비율 | C36: T열
A37: 수금 진행률 | B37: (수금된 선금 + 수금된 잔금) / 합계금액 | C37: W열
A39: ■ 새 견적서 추가 방법
A40: 1단계 | B40: ② 시트의 빈 행에 사업구분(드롭다운) 선택
A41: 2단계 | B41: No, 견적번호, 수요업체, 공급사, 견적일, 프로젝트유형, 견적명, 공급가액 입력
A42: 3단계 | B42: 부가세·합계금액·선금/잔금 금액은 자동 계산됨
A43: 4단계 | B43: 진행상태, 설치일정, 선금/잔금 입금일/상태는 진행 경과에 따라 업데이트
A44: 5단계 | B44: 대시보드(①)·수주현황(③)은 자동 반영 (별도 수정 불필요)
A46: ■ 새 사업 카테고리 추가
A47: 현재 | B47: 스마트 생태공장, 섬유 제조 자동화 2개
...
